2025-01-22 11:07:58.627 | ERROR    | __main__:main:243 - Case test failed. See error traceback below:
2025-01-22 11:07:58.681 | ERROR    | __main__:main:244 - Traceback (most recent call last):
  File "C:\Users\rudde\Documents\gst-resolve\gst-resolve\new_modeling_toolkit\resolve\run_opt.py", line 229, in main
    resolve_model = _run_case(
  File "C:\Users\rudde\Documents\gst-resolve\gst-resolve\new_modeling_toolkit\resolve\run_opt.py", line 125, in _run_case
    _, resolve_model = model_formulation.ResolveCase.from_csv(
  File "C:\Users\rudde\Documents\gst-resolve\gst-resolve\new_modeling_toolkit\core\component.py", line 432, in from_csv
    return cls._parse_vintages(
  File "C:\Users\rudde\Documents\gst-resolve\gst-resolve\new_modeling_toolkit\core\component.py", line 322, in _parse_vintages
    scalar_attrs = cls._parse_scalar_attributes(filename=filename, input_df=vintage_slice, scenarios=scenarios)
  File "C:\Users\rudde\Documents\gst-resolve\gst-resolve\new_modeling_toolkit\core\component.py", line 281, in _parse_scalar_attributes
    input_df.loc[input_df["attribute"].isin(attribute_names), :]
  File "C:\Users\rudde\anaconda3\envs\kit\lib\site-packages\pandas\util\_decorators.py", line 331, in wrapper
    return func(*args, **kwargs)
  File "C:\Users\rudde\anaconda3\envs\kit\lib\site-packages\pandas\core\frame.py", line 5399, in drop
    return super().drop(
  File "C:\Users\rudde\anaconda3\envs\kit\lib\site-packages\pandas\util\_decorators.py", line 331, in wrapper
    return func(*args, **kwargs)
  File "C:\Users\rudde\anaconda3\envs\kit\lib\site-packages\pandas\core\generic.py", line 4505, in drop
    obj = obj._drop_axis(labels, axis, level=level, errors=errors)
  File "C:\Users\rudde\anaconda3\envs\kit\lib\site-packages\pandas\core\generic.py", line 4546, in _drop_axis
    new_axis = axis.drop(labels, errors=errors)
  File "C:\Users\rudde\anaconda3\envs\kit\lib\site-packages\pandas\core\indexes\base.py", line 6934, in drop
    raise KeyError(f"{list(labels[mask])} not found in axis")
KeyError: "['timestamp'] not found in axis"

2025-01-22 11:07:58.708 | INFO     | __main__:main:250 - Done.
