2025-01-22 14:15:10.091 | WARNING  | new_modeling_toolkit.core.component:_filter_highest_scenario:141 - attributes has no data for active scenario(s): []
2025-01-22 14:15:10.096 | INFO     | new_modeling_toolkit.resolve.model_formulation:_get_settings:130 - Reading scenario settings
2025-01-22 14:15:10.105 | ERROR    | __main__:main:243 - Case test failed. See error traceback below:
2025-01-22 14:15:10.118 | ERROR    | __main__:main:244 - Traceback (most recent call last):
  File "C:\Users\rudde\anaconda3\envs\kit\lib\site-packages\pandas\core\indexes\base.py", line 3802, in get_loc
    return self._engine.get_loc(casted_key)
  File "pandas\_libs\index.pyx", line 138, in pandas._libs.index.IndexEngine.get_loc
  File "pandas\_libs\index.pyx", line 165, in pandas._libs.index.IndexEngine.get_loc
  File "pandas\_libs\hashtable_class_helper.pxi", line 5745, in pandas._libs.hashtable.PyObjectHashTable.get_item
  File "pandas\_libs\hashtable_class_helper.pxi", line 5753, in pandas._libs.hashtable.PyObjectHashTable.get_item
KeyError: 'scenarios'

The above exception was the direct cause of the following exception:

Traceback (most recent call last):
  File "C:\Users\rudde\Documents\gst-resolve\gst-resolve\new_modeling_toolkit\resolve\run_opt.py", line 229, in main
    resolve_model = _run_case(
  File "C:\Users\rudde\Documents\gst-resolve\gst-resolve\new_modeling_toolkit\resolve\run_opt.py", line 125, in _run_case
    _, resolve_model = model_formulation.ResolveCase.from_csv(
  File "C:\Users\rudde\Documents\gst-resolve\gst-resolve\new_modeling_toolkit\core\component.py", line 432, in from_csv
    return cls._parse_vintages(
  File "C:\Users\rudde\Documents\gst-resolve\gst-resolve\new_modeling_toolkit\core\component.py", line 334, in _parse_vintages
    vintages[attrs["name"]] = cls(**attrs)
  File "C:\Users\rudde\Documents\gst-resolve\gst-resolve\new_modeling_toolkit\resolve\model_formulation.py", line 101, in __init__
    kwargs = self._get_settings(kwargs)
  File "C:\Users\rudde\Documents\gst-resolve\gst-resolve\new_modeling_toolkit\resolve\model_formulation.py", line 131, in _get_settings
    scenarios = pd.read_csv(dir_str.resolve_settings_dir / "scenarios.csv")["scenarios"].tolist()
  File "C:\Users\rudde\anaconda3\envs\kit\lib\site-packages\pandas\core\frame.py", line 3807, in __getitem__
    indexer = self.columns.get_loc(key)
  File "C:\Users\rudde\anaconda3\envs\kit\lib\site-packages\pandas\core\indexes\base.py", line 3804, in get_loc
    raise KeyError(key) from err
KeyError: 'scenarios'

2025-01-22 14:15:10.124 | INFO     | __main__:main:250 - Done.
